Workbook
Name Task: OFFSET('Diễn giải 2'!$A$4,0,0,COUNTA('Diễn giải 2'!$A:$A)-1)

Sheet 01. Tổng task
A1: BÁO CÁO TỔNG HỢP CÔNG VIỆC TRONG THÁNG
A4: Họ tên: | H4: Hoàng Quý Đạt
A5: Kỳ báo cáo: | H5: 2026-10
A8: THỐNG KÊ CÔNG VIỆC | K8: ĐIỂM CÁ NHÂN ĐÁNH GIÁ | X8: CÔNG THỨC TỰ ĐỘNG (THÀNH VIÊN KHÔNG NHẬP - KHÔNG XÓA-SỬA)
K9: HIỆU QUẢ (I) | M9: CHẤT LƯỢNG (II) | P9: HỖ TRỢ KHÁCH HÀNG (III) | S9: QUY TRÌNH (IV) | X9: ĐIỂM SỐ | AB9: TRỌNG SỐ | AF9: Điểm KPI Task | AG9: Điểm quy đổi | AH9: ĐIỂM QUY ĐỔI = ĐIỂM TƯƠNG ỨNG * ĐỘ PHỨC TẠP | AL9: TỔNG TRỌNG SỐ = TRỌNG SỐ TƯƠNG ỨNG * ĐỘ PHỨC TẠP
A10: STT | B10: Nhóm dự án | C10: Mã - tên dự án | D10: Nội dung công việc | E10: Link base | F10: Ghi chú | G10: Loại công việc | H10: Số ngày thực hiện | I10: Độ phức tạp (1 → 5) | J10: Kế hoạch (%) | K10: Hoàn thành thực tế (%) | L10: Đúng hạn (1/0) | M10: Sổ lỗi (Bug) sau bàn giao | N10: Số lỗi nghiêm trọng (Bug Critical) | O10: Tỉ lệ đạt sau review (Review Pass) (%) | P10: SLA đúng hạn (%) | Q10: Phản hồi (giờ) | R10: Nghiệm thu lần đầu (1/0) | S10: Tài liệu đầy đủ (%) | T10: Tuân thủ quy trình (%) | U10: Sáng kiến (điểm 0-1) | V10: Tinh thần tích cực (điểm 0 -> 5) | W10: Thái độ chủ động (điểm 0 -> 5) | X10: Điểm hiệu quả | Y10: Điểm chất lượng | Z10: Điểm hỗ trợ | AA10: Điểm quy trình | AB10: Trọng số Hiệu quả | AC10: Trọng số Chất lượng | AD10: Trọng số Hỗ trợ | AE10: Trọng số Quy trình | AH10: Điểm Hiệu Qủa quy đổi | AI10: Điểm Chất Lượng quy đổi | AJ10: Điểm Hỗ Trợ quy đổi | AK10: Điểm Quy Trình quy đổi | AL10: Tổng trọng số Hiệu Quả | AM10: Tổng trọng số Chất Lượng | AN10: Tổng trọng số Hỗ trợ | AO10: Tổng trọng số quy trình
K11: (70%) | L11: (30%) | M11: (40%) | N11: (40%) | O11: (20%) | P11: (60%) | Q11: (20%) | R11: (20%) | S11: ('25%) | T11: (25%) | U11: (10%) | V11: (20%) | W11: (20%)
A12: ="("&COLUMNS($A:A)&")" -> (1) | B12: ="("&COLUMNS($A:B)&")" -> (2) | C12: ="("&COLUMNS($A:C)&")" -> (3) | D12: ="("&COLUMNS($A:D)&")" -> (4) | E12: ="("&COLUMNS($A:E)&")" -> (5) | F12: ="("&COLUMNS($A:F)&")" -> (6) | G12: ="("&COLUMNS($A:G)&")" -> (7) | H12: ="("&COLUMNS($A:H)&")" -> (8) | I12: ="("&COLUMNS($A:I)&")" -> (9) | J12: ="("&COLUMNS($A:J)&")" -> (10) | K12: ="("&COLUMNS($A:K)&")" -> (11) | L12: ="("&COLUMNS($A:L)&")" -> (12) | M12: ="("&COLUMNS($A:M)&")" -> (13) | N12: ="("&COLUMNS($A:N)&")" -> (14) | O12: ="("&COLUMNS($A:O)&")" -> (15) | P12: ="("&COLUMNS($A:P)&")" -> (16) | Q12: ="("&COLUMNS($A:Q)&")" -> (17) | R12: ="("&COLUMNS($A:R)&")" -> (18) | S12: ="("&COLUMNS($A:S)&")" -> (19) | T12: ="("&COLUMNS($A:T)&")" -> (20) | U12: ="("&COLUMNS($A:U)&")" -> (21) | V12: ="("&COLUMNS($A:V)&")" -> (22) | W12: ="("&COLUMNS($A:W)&")" -> (23) | X12: ="("&COLUMNS($A:X)&")" -> (24) | Y12: ="("&COLUMNS($A:Y)&")" -> (25) | Z12: ="("&COLUMNS($A:Z)&")" -> (26) | AA12: ="("&COLUMNS($A:AA)&")" -> (27) | AB12: ="("&COLUMNS($A:AB)&")" -> (28) | AC12: ="("&COLUMNS($A:AC)&")" -> (29) | AD12: ="("&COLUMNS($A:AD)&")" -> (30) | AE12: ="("&COLUMNS($A:AE)&")" -> (31) | AF12: ="("&COLUMNS($A:AF)&")" -> (32) | AG12: ="("&COLUMNS($A:AG)&")" -> (33) | AH12: ="("&COLUMNS($A:AH)&")" -> (34) | AI12: ="("&COLUMNS($A:AI)&")" -> (35) | AJ12: ="("&COLUMNS($A:AJ)&")" -> (36) | AK12: ="("&COLUMNS($A:AK)&")" -> (37) | AL12: ="("&COLUMNS($A:AL)&")" -> (38) | AM12: ="("&COLUMNS($A:AM)&")" -> (39) | AN12: ="("&COLUMNS($A:AN)&")" -> (40) | AO12: ="("&COLUMNS($A:AO)&")" -> (41)
A13: 1 | B13: ITS | C13: [SW2026] ITS015 - Hữu Nghị-Chi Lăng | D13: [2026] XD001.5.6 Service tích hợp dữ liệu 2 | E13: https://wework.base.vn/tasks?task=11034326 | F13: - Triển khai cơ chế gửi nối đuôi dữ liệu và gửi tức thì khi có dữ liệu mới - Xử lý luồng gửi dữ liệu: lấy dữ liệu từ CSDL và chuyển đổi đúng cấu trúc đối tác yêu cầu - Tự động đóng gói và ghi file dữ liệu gửi đi để lưu trữ làm bằng chứng đối soát - Chuẩn hóa luồng log cha - con và theo dõi fix bug kiểm thử F16 | G13: DEV | H13: 10.5 | I13: 4 | J13: 1 | K13: 1 | L13: 1 | M13: 1 | N13: 0 | O13: 0.8 | P13: 0 | Q13: 0 | R13: 0 | S13: 1 | T13: 1 | U13: 0 | V13: 4 | W13: 4 | X13: =IFERROR(MIN(100,(K13/J13)*100)*0.7+L13*100*0.3,0) -> 100 | Y13: =MAX(0,100-M13*15-N13*50)*0.8+IF(O13="",0,O13*100*0.2) -> 84 | Z13: =IF(P13="",0,P13*100*0.6)+IF(Q13="",0,IF(Q13<=4,100,MAX(0,100-(Q13-4)*10))*0.2)+IF(R13="",0,R13*100*0.2) -> 20 | AA13: =IF(COUNTA(S13:W13)=0,0,IF(S13="",0,S13*100*25%)+IF(T13="",0,T13*100*25%)+IF(U13="",0,MIN(1,U13)*100*10%)+IF(V13="",0,MIN(5,V13)/5*100*20%)+IF(W13="",0,MIN(5,W13)/5*100*20%)) -> 90 | AB13: =IFERROR(VLOOKUP(G13,'Diễn giải 2'!$A$4:$F$11,3,FALSE),0) -> 0.4 | AC13: =IFERROR(VLOOKUP(G13,'Diễn giải 2'!$A$4:$F$11,4,FALSE),0) -> 0.5 | AD13: =IFERROR(VLOOKUP(G13,'Diễn giải 2'!$A$4:$F$11,5,FALSE),0) -> 0 | AE13: =IFERROR(VLOOKUP(G13,'Diễn giải 2'!$A$4:$F$11,6,FALSE),0) -> 0.1 | AF13: =(X13*AB13+Y13*AC13+Z13*AD13+AA13*AE13) -> 91 | AG13: =AF13*I13 -> 0 | AH13: =X13*I13*AB13 -> 0 | AI13: =Y13*I13*AC13 -> 0 | AJ13: =Z13*I13*AD13 -> 0 | AK13: =AA13*I13*AE13 -> 0 | AL13: =I13*AB13 -> 0 | AM13: =I13*AC13 -> 0 | AN13: =I13*AD13 -> 0 | AO13: =I13*AE13 -> 0
A14: 2 | B14: ITS | C14: [SW2026] ITS015 - Hữu Nghị-Chi Lăng | D14: XD001.6.3. Service tích hợp thiết bị | E14: https://wework.base.vn/tasks?task=11004386 | F14: - Nghiên cứu tài liệu chuẩn giao tiếp ISAPI của thiết bị điều khiển màn hình - Xây dựng API và cơ chế phân quyền VideoWall theo người dùng, tổ chức và ô màn hình - Phát triển Worker Service giao tiếp thiết bị qua ISAPI/NATS - Xây dựng form WPF test thiết bị - Trực tiếp ra site kiểm thử thiết bị (2 ngày): kiểm tra kết nối phần cứng và điều khiển màn hình tại hiện trường | G14: DEV | H14: 10 | I14: 4 | J14: 1 | K14: 1 | L14: 1 | M14: 1 | N14: 0 | O14: 0.85 | P14: 0 | Q14: 0 | R14: 0 | S14: 1 | T14: 1 | U14: 0 | V14: 4 | W14: 4 | X14: =IFERROR(MIN(100,(K14/J14)*100)*0.7+L14*100*0.3,0) -> 0 | Y14: =MAX(0,100-M14*15-N14*50)*0.8+IF(O14="",0,O14*100*0.2) -> 80 | Z14: =IF(P14="",0,P14*100*0.6)+IF(Q14="",0,IF(Q14<=4,100,MAX(0,100-(Q14-4)*10))*0.2)+IF(R14="",0,R14*100*0.2) -> 0 | AA14: =IF(COUNTA(S14:W14)=0,0,IF(S14="",0,S14*100*25%)+IF(T14="",0,T14*100*25%)+IF(U14="",0,MIN(1,U14)*100*10%)+IF(V14="",0,MIN(5,V14)/5*100*20%)+IF(W14="",0,MIN(5,W14)/5*100*20%)) -> 0 | AB14: =IFERROR(VLOOKUP(G14,'Diễn giải 2'!$A$4:$F$11,3,FALSE),0) -> 0.4 | AC14: =IFERROR(VLOOKUP(G14,'Diễn giải 2'!$A$4:$F$11,4,FALSE),0) -> 0.5 | AD14: =IFERROR(VLOOKUP(G14,'Diễn giải 2'!$A$4:$F$11,5,FALSE),0) -> 0 | AE14: =IFERROR(VLOOKUP(G14,'Diễn giải 2'!$A$4:$F$11,6,FALSE),0) -> 0.1 | AF14: =(X14*AB14+Y14*AC14+Z14*AD14+AA14*AE14) -> 40 | AG14: =AF14*I14 -> 0 | AH14: =X14*I14*AB14 -> 0 | AI14: =Y14*I14*AC14 -> 0 | AJ14: =Z14*I14*AD14 -> 0 | AK14: =AA14*I14*AE14 -> 0 | AL14: =I14*AB14 -> 0 | AM14: =I14*AC14 -> 0 | AN14: =I14*AD14 -> 0 | AO14: =I14*AE14 -> 0
G15: DOC | X15: =IFERROR(MIN(100,(K15/J15)*100)*0.7+L15*100*0.3,0) -> 0 | Y15: =MAX(0,100-M15*15-N15*50)*0.8+IF(O15="",0,O15*100*0.2) -> 80 | Z15: =IF(P15="",0,P15*100*0.6)+IF(Q15="",0,IF(Q15<=4,100,MAX(0,100-(Q15-4)*10))*0.2)+IF(R15="",0,R15*100*0.2) -> 0 | AA15: =IF(COUNTA(S15:W15)=0,0,IF(S15="",0,S15*100*25%)+IF(T15="",0,T15*100*25%)+IF(U15="",0,MIN(1,U15)*100*10%)+IF(V15="",0,MIN(5,V15)/5*100*20%)+IF(W15="",0,MIN(5,W15)/5*100*20%)) -> 0 | AB15: =IFERROR(VLOOKUP(G15,'Diễn giải 2'!$A$4:$F$11,3,FALSE),0) -> 0.2 | AC15: =IFERROR(VLOOKUP(G15,'Diễn giải 2'!$A$4:$F$11,4,FALSE),0) -> 0.2 | AD15: =IFERROR(VLOOKUP(G15,'Diễn giải 2'!$A$4:$F$11,5,FALSE),0) -> 0 | AE15: =IFERROR(VLOOKUP(G15,'Diễn giải 2'!$A$4:$F$11,6,FALSE),0) -> 0.6 | AF15: =(X15*AB15+Y15*AC15+Z15*AD15+AA15*AE15) -> 16 | AG15: =AF15*I15 -> 0 | AH15: =X15*I15*AB15 -> 0 | AI15: =Y15*I15*AC15 -> 0 | AJ15: =Z15*I15*AD15 -> 0 | AK15: =AA15*I15*AE15 -> 0 | AL15: =I15*AB15 -> 0 | AM15: =I15*AC15 -> 0 | AN15: =I15*AD15 -> 0 | AO15: =I15*AE15 -> 0
G16: DEV | X16: =IFERROR(MIN(100,(K16/J16)*100)*0.7+L16*100*0.3,0) -> 0 | Y16: =MAX(0,100-M16*15-N16*50)*0.8+IF(O16="",0,O16*100*0.2) -> 80 | Z16: =IF(P16="",0,P16*100*0.6)+IF(Q16="",0,IF(Q16<=4,100,MAX(0,100-(Q16-4)*10))*0.2)+IF(R16="",0,R16*100*0.2) -> 0 | AA16: =IF(COUNTA(S16:W16)=0,0,IF(S16="",0,S16*100*25%)+IF(T16="",0,T16*100*25%)+IF(U16="",0,MIN(1,U16)*100*10%)+IF(V16="",0,MIN(5,V16)/5*100*20%)+IF(W16="",0,MIN(5,W16)/5*100*20%)) -> 0 | AB16: =IFERROR(VLOOKUP(G16,'Diễn giải 2'!$A$4:$F$11,3,FALSE),0) -> 0.4 | AC16: =IFERROR(VLOOKUP(G16,'Diễn giải 2'!$A$4:$F$11,4,FALSE),0) -> 0.5 | AD16: =IFERROR(VLOOKUP(G16,'Diễn giải 2'!$A$4:$F$11,5,FALSE),0) -> 0 | AE16: =IFERROR(VLOOKUP(G16,'Diễn giải 2'!$A$4:$F$11,6,FALSE),0) -> 0.1 | AF16: =(X16*AB16+Y16*AC16+Z16*AD16+AA16*AE16) -> 40 | AG16: =AF16*I16 -> 0 | AH16: =X16*I16*AB16 -> 0 | AI16: =Y16*I16*AC16 -> 0 | AJ16: =Z16*I16*AD16 -> 0 | AK16: =AA16*I16*AE16 -> 0 | AL16: =I16*AB16 -> 0 | AM16: =I16*AC16 -> 0 | AN16: =I16*AD16 -> 0 | AO16: =I16*AE16 -> 0
X17: =IFERROR(MIN(100,(K17/J17)*100)*0.7+L17*100*0.3,0) -> 0 | Y17: =MAX(0,100-M17*15-N17*50)*0.8+IF(O17="",0,O17*100*0.2) -> 0 | Z17: =IF(P17="",0,P17*100*0.6)+IF(Q17="",0,IF(Q17<=4,100,MAX(0,100-(Q17-4)*10))*0.2)+IF(R17="",0,R17*100*0.2) -> 0 | AA17: =IF(COUNTA(S17:W17)=0,0,IF(S17="",0,S17*100*25%)+IF(T17="",0,T17*100*25%)+IF(U17="",0,MIN(1,U17)*100*10%)+IF(V17="",0,MIN(5,V17)/5*100*20%)+IF(W17="",0,MIN(5,W17)/5*100*20%)) -> 0 | AB17: =IFERROR(VLOOKUP(G17,'Diễn giải 2'!$A$4:$F$11,3,FALSE),0) -> 0 | AC17: =IFERROR(VLOOKUP(G17,'Diễn giải 2'!$A$4:$F$11,4,FALSE),0) -> 0 | AD17: =IFERROR(VLOOKUP(G17,'Diễn giải 2'!$A$4:$F$11,5,FALSE),0) -> 0 | AE17: =IFERROR(VLOOKUP(G17,'Diễn giải 2'!$A$4:$F$11,6,FALSE),0) -> 0 | AF17: =(X17*AB17+Y17*AC17+Z17*AD17+AA17*AE17) -> 0 | AG17: =AF17*I17 -> 0 | AH17: =X17*I17*AB17 -> 0 | AI17: =Y17*I17*AC17 -> 0 | AJ17: =Z17*I17*AD17 -> 0 | AK17: =AA17*I17*AE17 -> 0 | AL17: =I17*AB17 -> 0 | AM17: =I17*AC17 -> 0 | AN17: =I17*AD17 -> 0 | AO17: =I17*AE17 -> 0
X18: =IFERROR(MIN(100,(K18/J18)*100)*0.7+L18*100*0.3,0) -> 0 | Y18: =MAX(0,100-M18*15-N18*50)*0.8+IF(O18="",0,O18*100*0.2) -> 0 | Z18: =IF(P18="",0,P18*100*0.6)+IF(Q18="",0,IF(Q18<=4,100,MAX(0,100-(Q18-4)*10))*0.2)+IF(R18="",0,R18*100*0.2) -> 0 | AA18: =IF(COUNTA(S18:W18)=0,0,IF(S18="",0,S18*100*25%)+IF(T18="",0,T18*100*25%)+IF(U18="",0,MIN(1,U18)*100*10%)+IF(V18="",0,MIN(5,V18)/5*100*20%)+IF(W18="",0,MIN(5,W18)/5*100*20%)) -> 0 | AB18: =IFERROR(VLOOKUP(G18,'Diễn giải 2'!$A$4:$F$11,3,FALSE),0) -> 0 | AC18: =IFERROR(VLOOKUP(G18,'Diễn giải 2'!$A$4:$F$11,4,FALSE),0) -> 0 | AD18: =IFERROR(VLOOKUP(G18,'Diễn giải 2'!$A$4:$F$11,5,FALSE),0) -> 0 | AE18: =IFERROR(VLOOKUP(G18,'Diễn giải 2'!$A$4:$F$11,6,FALSE),0) -> 0 | AF18: =(X18*AB18+Y18*AC18+Z18*AD18+AA18*AE18) -> 0 | AG18: =AF18*I18 -> 0 | AH18: =X18*I18*AB18 -> 0 | AI18: =Y18*I18*AC18 -> 0 | AJ18: =Z18*I18*AD18 -> 0 | AK18: =AA18*I18*AE18 -> 0 | AL18: =I18*AB18 -> 0 | AM18: =I18*AC18 -> 0 | AN18: =I18*AD18 -> 0 | AO18: =I18*AE18 -> 0
X19: =IFERROR(MIN(100,(K19/J19)*100)*0.7+L19*100*0.3,0) -> 0 | Y19: =MAX(0,100-M19*15-N19*50)*0.8+IF(O19="",0,O19*100*0.2) -> 0 | Z19: =IF(P19="",0,P19*100*0.6)+IF(Q19="",0,IF(Q19<=4,100,MAX(0,100-(Q19-4)*10))*0.2)+IF(R19="",0,R19*100*0.2) -> 0 | AA19: =IF(COUNTA(S19:W19)=0,0,IF(S19="",0,S19*100*25%)+IF(T19="",0,T19*100*25%)+IF(U19="",0,MIN(1,U19)*100*10%)+IF(V19="",0,MIN(5,V19)/5*100*20%)+IF(W19="",0,MIN(5,W19)/5*100*20%)) -> 0 | AB19: =IFERROR(VLOOKUP(G19,'Diễn giải 2'!$A$4:$F$11,3,FALSE),0) -> 0 | AC19: =IFERROR(VLOOKUP(G19,'Diễn giải 2'!$A$4:$F$11,4,FALSE),0) -> 0 | AD19: =IFERROR(VLOOKUP(G19,'Diễn giải 2'!$A$4:$F$11,5,FALSE),0) -> 0 | AE19: =IFERROR(VLOOKUP(G19,'Diễn giải 2'!$A$4:$F$11,6,FALSE),0) -> 0 | AF19: =(X19*AB19+Y19*AC19+Z19*AD19+AA19*AE19) -> 0 | AG19: =AF19*I19 -> 0 | AH19: =X19*I19*AB19 -> 0 | AI19: =Y19*I19*AC19 -> 0 | AJ19: =Z19*I19*AD19 -> 0 | AK19: =AA19*I19*AE19 -> 0 | AL19: =I19*AB19 -> 0 | AM19: =I19*AC19 -> 0 | AN19: =I19*AD19 -> 0 | AO19: =I19*AE19 -> 0
A20: TỔNG KẾT | H20: =SUM(H13:H19) -> 20.5 | I20: =SUM(I13:I19) -> 8 | X20: =IFERROR(SUM(AH13:AH19)/SUM(AL13:AL19),0) -> 98.352941 | Y20: =IFERROR(SUM(AI13:AI19)/SUM(AM13:AM19),0) -> 94.833333 | Z20: =IFERROR(SUM(AJ13:AJ19)/SUM(AN13:AN19),0) -> 100 | AA20: =IFERROR(SUM(AK13:AK19)/SUM(AO13:AO19),0) -> 87.6875 | AB20: =IFERROR(SUM(AL13:AL19)/SUM(I13:I19),0) -> 0.425 | AC20: =IFERROR(SUM(AM13:AM19)/SUM(I13:I19),0) -> 0.3 | AD20: =IFERROR(SUM(AN13:AN19)/SUM(I13:I19),0) -> 0.075 | AE20: =IFERROR(SUM(AO13:AO19)/SUM(I13:I19),0) -> 0.2 | AF20: =IFERROR(SUM(AG13:AG19)/SUM(I13:I19),0) -> 95.2875 | AG20: =SUM(AG13:AG19) -> 762.3 | AH20: =SUM(AH13:AH19) -> 334.4 | AI20: =SUM(AI13:AI19) -> 227.6 | AJ20: =SUM(AJ13:AJ19) -> 60 | AK20: =SUM(AK13:AK19) -> 140.3 | AL20: =SUM(AL13:AL19) -> 3.4 | AM20: =SUM(AM13:AM19) -> 2.4 | AN20: =SUM(AN13:AN19) -> 0.6 | AO20: =SUM(AO13:AO19) -> 1.6
A27: THANG ĐIỂM KPI | E27: LOẠI CÔNG VIỆC
B28: 95 - 100 | C28: Xuất sắc | G28: Phát triển | K28: Tài liệu
B29: 90 - 94 | C29: Tốt | G29: Xây dựng API | K29: Kiểm tra code
B30: 80 - 89 | C30: Khá | G30: Sửa lỗi | K30: Bảo trì
B31: 70 - 79 | C31: Đạt | G31: Hỗ trợ | K31: Nghiên cứu
B32: < 70 | C32: Chưa đạt

Sheet 02. Tổng KPI
A1: BÁO CÁO ĐÁNH GIÁ KPI VÀ KẾ HOẠCH PHÁT TRIỂN CÁ NHÂN
A5: THÔNG TIN NHÂN SỰ VÀ KỲ ĐÁNH GIÁ
A6: Họ tên nhân viên | C6: ='01. Tổng task'!H4 -> Hoàng Quý Đạt | E6: Chức vụ | H6: Nhân viên phát triển phần mềm | K6: Ngày bắt đầu vào làm | M6: 45701
A7: Phòng ban | C7: Phòng phát triển phần mềm | E7: Quản lý | H7: Trần Hồng Sơn | K7: Ngày báo cáo | M7: 46312
A8: Kỳ đánh giá | C8: ='01. Tổng task'!H5 -> 2026-10 | E8: Chức vụ quản lý
A10: A. KẾT QUẢ THỰC HIỆN CÔNG VIỆC
A11: STT | B11: Dự án (tự động) | C11: Nội dung công việc chính (tự động) | G11: Kết quả nổi bật (thủ công) | M11: Số Task (tự động) | N11: Độ phức tạp (tự động) | O11: Điểm KPI Task (tự động)
A12: 1 | B12: {=IFERROR(INDEX('01. Tổng task'!$C$13:$C$109,MATCH(0,COUNTIF($B$11:B11,'01. Tổng task'!$C$13:$C$109)+IF('01. Tổng task'!$C$13:$C$109="",1,0),0)),"")} -> [SW2026] ITS015 - Hữu Nghị-Chi Lăng | C12: =P12 -> [2026] XD001.5.6 Service tích hợp dữ liệu 2 XD001.6.3. Service tích hợp thiết bị | M12: =COUNTIF('01. Tổng task'!$C$13:$C$19,B12) -> 2 | N12: =SUMIF('01. Tổng task'!$C$13:$C$19,B12,'01. Tổng task'!$I$13:$I$19) -> 8 | O12: =IFERROR(SUMPRODUCT(('01. Tổng task'!$C$13:$C$19=$B12)*'01. Tổng task'!$I$13:$I$19*'01. Tổng task'!$AF$13:$AF$19)/SUMIF('01. Tổng task'!$C$13:$C$19,$B12,'01. Tổng task'!$I$13:$I$19),0) -> 100 | P12: {=IF($B12="","",_xlfn.TEXTJOIN(CHAR(10),TRUE,IF('01. Tổng task'!$C$13:$C$109=$B12,'01. Tổng task'!$D$13:$D$109,"")))} -> [2026] XD001.5.6 Service tích hợp dữ liệu 2 XD001.6.3. Service tích hợp thiết bị
A13: 2 | B13: {=IFERROR(INDEX('01. Tổng task'!$C$13:$C$109,MATCH(0,COUNTIF($B$11:B12,'01. Tổng task'!$C$13:$C$109)+IF('01. Tổng task'!$C$13:$C$109="",1,0),0)),"")} | C13: =P13 | M13: =COUNTIF('01. Tổng task'!$C$13:$C$19,B13) -> 0 | N13: =SUMIF('01. Tổng task'!$C$13:$C$19,B13,'01. Tổng task'!$I$13:$I$19) -> 0 | O13: {=IFERROR(SUMPRODUCT(('01. Tổng task'!$C$13:$C$19=$B13)*'01. Tổng task'!$I$13:$I$19*'01. Tổng task'!$AF$13:$AF$19)/SUMIF('01. Tổng task'!$C$13:$C$19,$B13,'01. Tổng task'!$I$13:$I$19),0)} -> 0 | P13: {=IF($B13="","",_xlfn.TEXTJOIN(CHAR(10),TRUE,IF('01. Tổng task'!$C$13:$C$109=$B13,'01. Tổng task'!$D$13:$D$109,"")))} -> 0
A14: TỔNG | M14: =SUM(M12:M13) -> 1 | N14: =SUM(N12:N13) -> 0 | O14: =IFERROR(AVERAGEIF(B12:B13,"?*",O12:O13),0) -> 0
A16: B. ĐÁNH GIÁ NĂNG LỰC VÀ HÀNH VI (Thang điểm: 0 → 10)
A17: STT | B17: Nhóm năng lực | D17: Nội dung đánh giá | G17: Trọng số | H17: Điểm cá nhân (thủ công) | I17: Điểm quản lý (thủ công) | J17: Quy đổi cá nhân (tự động) | K17: Quy đổi quản lý (tự động) | L17: Nhận xét/ Ghi chú (thủ công)
A18: 1 | B18: Kiến thức và năng lực chuyên môn | D18: Hiểu nghiệp vụ, công nghệ; phân tích và giải quyết vấn đề | G18: 0.4 | H18: 8 | J18: =H18*G18 -> 0 | K18: =I18*G18 -> 0
A19: 2 | B19: Chủ động, trách nhiệm và phối hợp | D19: Chủ động nhận việc, cảnh báo rủi ro, phối hợp và chịu trách nhiệm | G19: 0.3 | H19: 8 | J19: =H19*G19 -> 0 | K19: =I19*G19 -> 0
A20: 3 | B20: Giải quyết vấn đề và cải tiến | D20: Đề xuất giải pháp, cải tiến công cụ/quy trình, chia sẻ kiến thức | G20: 0.2 | H20: 8 | J20: =H20*G20 -> 0 | K20: =I20*G20 -> 0
A21: 4 | B21: Học hỏi và phát triển | D21: Học công nghệ/nghiệp vụ mới và áp dụng vào thực tế | G21: 0.1 | H21: 8 | J21: =H21*G21 -> 0 | K21: =I21*G21 -> 0
A22: TỔNG | G22: =SUM(G18:G21) -> 1 | J22: =SUM(J18:J21) -> 0 | K22: =SUM(K18:K21) -> 0
A24: C. TỔNG HỢP KPI VÀ XẾP LOẠI (tự động)
A25: Nhóm KPI | C25: Trọng số chuẩn | D25: Điểm thực tế | F25: Điểm quy đổi
A26: Hiệu quả thực hiện công việc | C26: 0.4 | D26: =IFERROR(SUM('01. Tổng task'!$AH$13:$AH$516)/SUM('01. Tổng task'!$AL$13:$AL$516),0) -> 98.352941 | F26: =C26*D26 -> 39.341176
A27: Chất lượng sản phẩm phần mềm | C27: 0.35 | D27: =IFERROR(SUM('01. Tổng task'!$AI$13:$AI$516)/SUM('01. Tổng task'!$AM$13:$AM$516),0) -> 94.833333 | F27: =C27*D27 -> 33.191667
A28: Hỗ trợ & dịch vụ khách hàng | C28: 0.15 | D28: =IFERROR(SUM('01. Tổng task'!$AJ$13:$AJ$516)/SUM('01. Tổng task'!$AN$13:$AN$516),0) -> 100 | F28: =C28*D28 -> 15
A29: Quy trình & phát triển năng lực | C29: 0.1 | D29: =IFERROR(SUM('01. Tổng task'!$AK$13:$AK$19)/SUM('01. Tổng task'!$AO$13:$AO$19),0) -> 87.6875 | F29: =C29*D29 -> 8.76875
A30: TỔNG CỘNG | C30: 1 | F30: =SUM($F$26:$F$29) -> 96.301593
A35: TỔNG KẾT ĐIỂM (tự động) | I35: THANG ĐIỂM KPI
A36: Chỉ số tổng hợp | C36: Giá trị | D36: Ghi chú | J36: 95 - 100 | K36: Xuất sắc | L36: =_xlfn.UNICHAR(9733)&_xlfn.UNICHAR(9733)&_xlfn.UNICHAR(9733)&_xlfn.UNICHAR(9733)&_xlfn.UNICHAR(9733) -> ★★★★★
A37: TỔNG TASK | C37: =COUNT('01. Tổng task'!$A$13:$A$516) -> 2 | D37: Tổng số đầu việc trong kỳ | J37: 90 - 94 | K37: Tốt | L37: =_xlfn.UNICHAR(9733)&_xlfn.UNICHAR(9733)&_xlfn.UNICHAR(9733)&_xlfn.UNICHAR(9733) -> ★★★★
A38: TỔNG TASK PHỨC TẠP | C38: =SUMIFS('01. Tổng task'!$I$13:$I$516,'01. Tổng task'!$A$13:$A$516,">0") -> 0 | D38: Tổng hệ số độ phức tạp | J38: 80 - 89 | K38: Khá | L38: =_xlfn.UNICHAR(9733)&_xlfn.UNICHAR(9733)&_xlfn.UNICHAR(9733) -> ★★★
A39: ĐIỂM KPI TASK | C39: =IFERROR(SUMIFS('01. Tổng task'!$AG$13:$AG$516,'01. Tổng task'!$A$13:$A$516,">0")/SUMIFS('01. Tổng task'!$I$13:$I$516,'01. Tổng task'!$A$13:$A$516,">0"),0) -> 0 | D39: Bình quân điểm theo dự án | J39: 70 - 79 | K39: Đạt | L39: =_xlfn.UNICHAR(9733)&_xlfn.UNICHAR(9733) -> ★★
A40: ĐIỂM KPI TIÊU CHÍ | C40: =SUM($F$26:$F$29) -> 96.301593 | D40: Tổng điểm quy đổi theo 4 nhóm KPI. Theo trọng số 40%-35%-15%-10% | J40: < 70 | K40: Chưa đạt | L40: =_xlfn.UNICHAR(9888) -> ⚠
A41: ĐIỂM NĂNG LỰC | C41: =IFERROR($K$22/10*80+$J$22/10*20,0) -> 0 | D41: Bình quân điểm của đánh giá năng lực và hành vi. Quy đổi thang 10 sang 100 Quản lý * 80% + Thành viên * 20%
A42: ĐIỂM KPT TỔNG | C42: =C40*80%+C41*20% -> 77.041275 | D42: 80% KPI công việc + 20% năng lực
A43: XẾP LOẠI | C43: =IF(C42>=95,"Xuất sắc",IF(C42>=90,"Tốt",IF(C42>=80,"Khá",IF(C42>=70,"Đạt","Chưa đạt")))) -> Đạt | D43: =IF(C43="Xuất sắc",_xlfn.UNICHAR(9733)&_xlfn.UNICHAR(9733)&_xlfn.UNICHAR(9733)&_xlfn.UNICHAR(9733)&_xlfn.UNICHAR(9733),IF(C43="Tốt",_xlfn.UNICHAR(9733)&_xlfn.UNICHAR(9733)&_xlfn.UNICHAR(9733)&_xlfn.UNICHAR(9733),IF(C43="Khá",_xlfn.UNICHAR(9733)&_xlfn.UNICHAR(9733)&_xlfn.UNICHAR(9733),IF(C43="Đạt",_xlfn.UNICHAR(9733)&_xlfn.UNICHAR(9733),IF(C43="Chưa đạt",_xlfn.UNICHAR(10006),""))))) -> ★★
A45: D. KẾ HOẠCH VÀ MỤC TIÊU KỲ TIẾP THEO
A46: STT | B46: Mã dự án | C46: Tên dự án | D46: Tháng 01 | E46: Tháng 02 | F46: Tháng 03 | G46: Tháng 04 | H46: Tháng 05 | I46: Tháng 06 | J46: Tháng 07 | K46: Tháng 08 | L46: Tháng 09 | M46: Tháng 10 | N46: Tháng 11 | O46: Tháng 12
A47: 1 | B47: ITS | C47: [SW2026] ITS015 - Hữu Nghị-Chi Lăng
A49: 3
A50: 4
A52: E. KẾ HOẠCH ĐÀO TẠO - HỌC TẬP
A53: STT | B53: Nội dung đào tạo | C53: Thời hạn | D53: Kết quả mong đợi | H53: Ghi chú
...

Sheet Diễn giải 1
A1: 4 TIÊU CHÍ ĐÁNH GIÁ KPI
A3: Chỉ tiêu đánh giá | B3: Chỉ tiêu con | C3: Tỉ trọng (%) | D3: Ý nghĩa | E3: Mục tiêu KPI
A4: HIỆU QUẢ (I) | B4: Hoàn thành thực tế (%) | C4: 70 | D4: Phần trăm hoàn thành thực hiện được so với kế hoạch - mục tiêu đặt ra | E4: ≥90%
B5: Đúng hạn (1/0) | C5: 30 | D5: Hoàn thành đúng hạn : 1 đ Hoàn trành trễ hạn: 0đ | E5: ≥95%
A6: CHẤT LƯỢNG (II) | B6: Sổ lỗi (Bug) sau bàn giao | C6: 40 | D6: Số lượng lỗi phát hiện sau khi phát hành sản phẩm (release). Tối đa: 100đ; tối thiểu 0đ Mỗi bug trừ 15đ | E6: ≤2 bugs/ tháng
B7: Số lỗi ngiệm trọng (Bug Critical) | C7: 40 | D7: Số lượng lỗi nghiêm trọng sau khi phát hành sản phẩm (release) Tối đa: 100đ; tối thiểu 0đ Mỗi bug trừ 50đ | E7: ≤0 bugs/ tháng
B8: Tỉ lệ code đạt sau review (Code Review Pass) (%) | C8: 20 | D8: Tỉ lệ tổng = số review đạt/tổng số yêu cầu Ví dụ: Tổng PR = 40 Tổng review đạt = 36 Tĩ lệ = 36/40 = 90% | E8: ≥95%
A9: HỖ TRỢ KHÁCH HÀNG (III) | B9: SLA đúng hạn (%) | C9: 60 | D9: Tỷ lệ yêu cầu hỗ trợ được xử lý đúng thời gian cam kết (SLA). *Công thức: Số ticket đúng SLA / Tổng ticket × 100% | E9: ≥95%
B10: Phản hồi (giờ) | C10: 20 | D10: Thời gian từ lúc khách hàng tạo yêu cầu đến lúc nhân viên phản hồi đầu tiên. *Công thức: Thời gian phản hồi đầu tiên - Thời gian tạo ticket | E10: ≤2 giờ (giờ hành chánh - ngày làm việc) <=24h (ngày nghỉ)
B11: Nghiệm thu lần đầu (1/0) | C11: 20 | D11: Ticket được khách hàng chấp nhận ngay lần đầu hay không. *Công thức: 1 = Đồng ý ngay, 0 = Phải sửa lại | E11: ≥90%
A12: QUY TRÌNH (IV) | B12: Tài liệu đầy đủ (%) | C12: 25 | D12: Đảm bảo mọi công việc đều có tài liệu phục vụ bảo trì và bàn giao. Kiểm tra checklist tài liệu bắt buộc của từng loại task (BRD, API, DB, Test Case, Release Note, HDSD...). *Công thức: Điểm = Số tài liệu hoàn thành / Số tài liệu yêu cầu × 100%. | E12: ≥95%
B13: Tuân thủ quy trình (%) | C13: 25 | D13: Thực hiện đúng quy trình phát triển phần mềm của công ty. Đánh giá theo checklist quy trình: tạo Task → Code → Pull Request → Code Review → Test → UAT → Update realses, tài liệu drive, nhật ký → Release → Close Task. *Công thức: Điểm = Bước hoàn thành / Bước yêu cầu ×100%. | E13: ≥95%
B14: Sáng kiến (điểm 0-1) | C14: 10 | D14: Khuyến khích cải tiến quy trình, công cụ hoặc sản phẩm. *Công thức: 0 = Không có. 0.5 = Có đề xuất nhưng chưa áp dụng. 1 = Đề xuất được áp dụng hoặc mang lại hiệu quả rõ ràng. | E14: Trung bình ≥0.5/tháng
B15: Tinh thần tích cực (điểm 0 -> 5) | C15: 20 | D15: | Điểm | Mô tả | | ----- | --------------------------------------------------------------------------- | | **5** | Luôn tích cực, hỗ trợ đồng nghiệp, tạo động lực cho nhóm, không than phiền. | | **4** | Hợp tác tốt, thái độ tích cực, đôi lúc cần nhắc nhở nhỏ. | | **3** | Hoàn thành công việc nhưng ít tương tác hoặc ít hỗ trợ. | | **2** | Thường xuyên tiêu cực, ảnh hưởng đến nhóm. | | **1** | Thái độ kém, gây xung đột. | | **0** | Vi phạm nghiêm trọng văn hóa công ty. | | E15: ≥4.5/5
B16: Thái độ chủ động (điểm 0 -> 5) | C16: 20 | D16: | Điểm | Mô tả | | ----- | ---------------------------------------------------------------------------- | | **5** | Chủ động nhận việc, phát hiện rủi ro, đề xuất giải pháp trước khi được giao. | | **4** | Chủ động trong phần lớn công việc, báo cáo kịp thời. | | **3** | Làm khi được giao, ít đề xuất. | | **2** | Thường xuyên chờ chỉ đạo, ít phản hồi. | | **1** | Né tránh trách nhiệm hoặc đùn đẩy công việc. | | **0** | Không hợp tác, ảnh hưởng nghiêm trọng đến tiến độ. | | E16: ≥4.5/5
A18: ĐỘ PHỨC TẠP CỦA TASK
A20: MỨC ĐỘ | B20: TIÊU CHÍ | C20: ĐIỂM | D20: PHÂN LOẠI | E20: VÍ DỤ
A21: Rất đơn giản | B21: Sửa text, CSS, cấu hình, dữ liệu, lỗi nhỏ, tài liệu đơn giản | C21: 1 | E21: | Công việc | Điểm | | ------------------ | -------| | Thêm nút In | 1 | | Sửa lỗi Validate| 1 | | Sửa lỗi API | 2 | | Viết API CRUD | 2 | | Dashboard mới | 3 | | Module hóa đơn| 4 | | Tích hợp SAP | 5 | | Thiết kế kiến trúc| 5 |
A22: Đơn giản | B22: Sửa bug nhỏ, API đơn giản, CRUD, hỗ trợ người dùng | C22: 2
A23: Trung bình | B23: Xây dựng màn hình mới, tích hợp API, báo cáo, module nhỏ | C23: 3
A24: Khó | B24: Module lớn, nhiều business, nhiều bảng DB, nhiều API | C24: 4
A25: Rất khó | B25: Thiết kế kiến trúc, tích hợp hệ thống, tối ưu hiệu năng, AI, phân tán, bảo mật | C25: 5
A27: Checklist - Code Review Pass
A29: Tiêu chí | B29: Ý nghĩa | D29: Ví dụ đạt | E29: Ví dụ không đạt
A30: 1. Coding Convention | B30: Tuân thủ quy ước viết code của dự án (format, style, tổ chức code). | D30: Đặt {} đúng chuẩn, indent 4 spaces, namespace đúng. | E30: File mỗi người một kiểu, format lộn xộn.
A31: 2. Naming | B31: Đặt tên biến, hàm, class rõ nghĩa và thống nhất. | D31: GetCustomerById(), userName. | E31: abc(), temp1, x, data2.
A32: 3. SOLID | B32: Tuân thủ 5 nguyên tắc thiết kế hướng đối tượng để code dễ mở rộng và bảo trì. | D32: Mỗi class chỉ có một trách nhiệm, dùng interface hợp lý. | E32: Một class vừa xử lý DB, vừa gửi email, vừa tính toán nghiệp vụ.
A33: 4. Clean Code | B33: Code dễ đọc, dễ hiểu, ít lặp lại, tổ chức logic rõ ràng. | D33: Hàm 20–30 dòng, chia nhỏ theo chức năng. | E33: Hàm 500 dòng, nhiều if-else lồng nhau, copy-paste nhiều nơi.
A34: 5. Security | B34: Đảm bảo an toàn dữ liệu và quyền truy cập. | D34: Kiểm tra quyền, mã hóa dữ liệu nhạy cảm, validate input. | E34: Lộ mật khẩu, API không kiểm tra quyền, lưu password dạng plain text.
A35: 6. Performance | B35: Tối ưu hiệu năng, tránh xử lý thừa. | D35: Query đúng index, phân trang, cache hợp lý. | E35: Query toàn bảng, gọi API lặp nhiều lần, vòng lặp dư thừa.
A36: 7. Exception Handling | B36: Bắt và xử lý lỗi đúng cách. | D36: try-catch có log, trả thông báo phù hợp. | E36: Nuốt lỗi (catch {}), hoặc để exception làm crash hệ thống.
A37: 8. SQL Injection | B37: Ngăn chặn tấn công chèn câu lệnh SQL. | D37: Dùng ORM (SqlSugar, EF Core) hoặc parameterized query. | E37: Ghép chuỗi SQL: "... WHERE Name = '" + name + "'".
A38: 9. Null Checking | B38: Kiểm tra giá trị null trước khi sử dụng. | D38: if (user == null) return;, ?., ??. | E38: Gọi user.Name khi user có thể bằng null, gây NullReferenceException.
A39: 10. Logging | B39: Ghi log đầy đủ để hỗ trợ giám sát và điều tra lỗi. | D39: Log lỗi với mã giao dịch, thời gian, stack trace. | E39: Không log hoặc chỉ log "Error" khiến không thể truy vết.
A40: 11. Unit Test | B40: Có kiểm thử tự động cho các logic quan trọng. | D40: Test các hàm tính toán, nghiệp vụ, API. | E40: Không có test hoặc test quá sơ sài.
... A42: 13. QAQC | B42: Theo dõi kết quả sau hỗ trợ không nhận phản hồi tiêu cực | D42: - Nhận thông tin tích cực - Không phát sinh lỗi | E42: Nhận ý kiến phàn nàn Phát sinh lỗi nghiêm trọng làm đứng/treo/ảnh hưởng vận hành

Sheet Diễn giải 2
A1: MA TRẬN TRỌNG SỐ KPI THEO LOẠI CÔNG VIỆC
A3: Mã loại | B3: Loại công việc | C3: Hiệu quả | D3: Chất lượng | E3: Hỗ trợ | F3: Quy trình & phát triển | G3: Tổng
A4: DEV | B4: Phát triển tính năng/module mới | C4: 0.4 | D4: 0.5 | E4: 0 | F4: 0.1 | G4: =SUM(C4:F4) -> 1
A5: API | B5: Phát triển API/Integration | C5: 0.4 | D5: 0.5 | E5: 0 | F5: 0.1 | G5: =SUM(C5:F5) -> 1
A6: BUG | B6: Sửa lỗi phần mềm | C6: 0.3 | D6: 0.4 | E6: 0.2 | F6: 0.1 | G6: =SUM(C6:F6) -> 1
A7: MAINT | B7: Bảo trì/nâng cấp hệ thống | C7: 0.3 | D7: 0.3 | E7: 0.3 | F7: 0.1 | G7: =SUM(C7:F7) -> 1
A8: SUPPORT | B8: Hỗ trợ khách hàng/end-user | C8: 0.2 | D8: 0.1 | E8: 0.6 | F8: 0.1 | G8: =SUM(C8:F8) -> 1
A9: RND | B9: Nghiên cứu/đề xuất giải pháp | C9: 0.5 | D9: 0.2 | E9: 0 | F9: 0.3 | G9: =SUM(C9:F9) -> 1
A10: DOC | B10: Viết tài liệu/hướng dẫn | C10: 0.2 | D10: 0.2 | E10: 0 | F10: 0.6 | G10: =SUM(C10:F10) -> 1
A11: REVIEW | B11: Review code/hỗ trợ kỹ thuật | C11: 0.2 | D11: 0.7 | E11: 0 | F11: 0.1 | G11: =SUM(C11:F11) -> 1
A13: THANG ĐIỂM KPI
B14: 95 - 100 | C14: Xuất sắc
B15: 90 - 94 | C15: Tốt
B16: 80 - 89 | C16: Khá
B17: 70 - 79 | C17: Đạt
B18: < 70 | C18: Chưa đạt
A20: HƯỚNG DẪN ÁP DỤNG KPI THEO TỪNG ĐẦU MỤC CÔNG VIỆC
A22: Nguyên tắc | D22: Diễn giải
A23: 1. Không ép một Task phải đủ 4 nhóm KPI | D23: Mỗi loại công việc chỉ áp dụng các nhóm KPI phù hợp thông qua ma trận trọng số.
A24: 2. Chấm điểm theo từng Task | D24: Nhập số liệu thực tế của Task; các điểm nhóm được Excel tự động tính.
A25: 3. Tổng hợp theo kỳ | D25: Điểm KPI tháng/quý là bình quân gia quyền theo độ phức tạp và trọng số áp dụng của từng Task.
A26: 4. Task không áp dụng tiêu chí | D26: Trọng số nhóm KPI của loại Task đó bằng 0%; tiêu chí không làm giảm điểm nhân viên.
A27: 5. Quy tắc trọng số | D27: Tổng trọng số của mỗi loại công việc phải bằng 100%.
A29: CÔNG THỨC TỔNG HỢP
A30: Điểm hiệu quả Task | C30: 70% × tỷ lệ hoàn thành so với kế hoạch + 30% × đúng hạn
A31: Điểm chất lượng Task | C31: 40% × điểm lỗi lọt sau kiểm thử + 40% × điểm lỗi nghiêm trọng lọt sau kiểm thử + 20% × tỷ lệ Test Case Review Pass
A32: Điểm hỗ trợ Task | C32: 60% × SLA + 20% × điểm thời gian phản hồi + 20% × nghiệm thu lần đầu
A33: Điểm quy trình Task | C33: 40% × tài liệu + 40% × tuân thủ quy trình + 20% × sáng kiến
A34: Điểm KPI Task | C34: Tổng (Điểm nhóm × Trọng số nhóm theo loại công việc)
A35: KPI kỳ đánh giá | C35: Tổng điểm quy đổi của các Task / Tổng trọng số quy đổi của các Task
